<?xml version="1.0" encoding="UTF-8"?>
<!-- Generated by org.testng.reporters.JUnitXMLReporter -->
<testsuite hostname="DESKTOP-OO3PNTG" ignored="0" tests="4" failures="2" timestamp="13 Jul 2021 13:20:16 GMT" time="0.129" errors="0">
  <testcase name="add1Test" time="0.027" classname="CalculatorTest"/>
  <testcase name="add1Test" time="0.013" classname="CalculatorTest">
    <failure type="java.lang.AssertionError" message="expected [20] but found [15]">
      <![CDATA[java.lang.AssertionError: expected [20] but found [15]
at CalculatorTest.add1Test(CalculatorTest.java:45)
at java.util.concurrent.FutureTask.run(Unknown Source)
at java.util.concurrent.ThreadPoolExecutor.runWorker(Unknown Source)
at java.util.concurrent.ThreadPoolExecutor$Worker.run(Unknown Source)
at java.lang.Thread.run(Unknown Source)
... Removed 22 stack frames]]>
    </failure>
  </testcase> <!-- add1Test -->
  <testcase name="add1Test" time="0.001" classname="CalculatorTest"/>
  <testcase name="add1Test" time="0.001" classname="CalculatorTest">
    <failure type="java.lang.AssertionError" message="expected [50] but found [31]">
      <![CDATA[java.lang.AssertionError: expected [50] but found [31]
at CalculatorTest.add1Test(CalculatorTest.java:45)
at java.util.concurrent.FutureTask.run(Unknown Source)
at java.util.concurrent.ThreadPoolExecutor.runWorker(Unknown Source)
at java.util.concurrent.ThreadPoolExecutor$Worker.run(Unknown Source)
at java.lang.Thread.run(Unknown Source)
... Removed 22 stack frames]]>
    </failure>
  </testcase> <!-- add1Test -->
</testsuite>
